Workbook

Sheet Чек-лист
A1: № | B1: Блок | C1: Задача | D1: Кто | E1: Приоритет | F1: Как / команда | G1: Статус | H1: Заметки
A2: 1 | B2: 1. Безопасность (пароли и ключи) | C2: Перевыпустить CLIENT_SECRET у поставщика САЛЮТ-1 (старый светился в переписке) и обновить SALUT_SECRET в /etc/bs.env | D2: Вы + я | E2: Высокий | F2: Старый ключ после замены перестанет работать. После: node sync.js --auth | G2: Не начато
A3: 2 | B3: 1. Безопасность (пароли и ключи) | C3: Отозвать старые токены Telegram-ботов в @BotFather (/revoke), создать новые, обновить ALERT_TOKEN | D3: Вы + я | E3: Высокий | F3: Токены показывались в чате | G3: Не начато
A4: 3 | B4: 1. Безопасность (пароли и ключи) | C4: Сменить PIN-коды сотрудников в приложении заказов (Владимир, Максим и др.) | D4: Вы | E4: Высокий | F4: Приложение заказов → Команда | G4: Не начато
A5: 4 | B5: 1. Безопасность (пароли и ключи) | C5: Сменить пароль root на сервере и перейти на вход по SSH-ключу; отключить вход по паролю | D5: Вы + я | E5: Высокий | F5: Проверить: grep -E "PasswordAuthentication|PermitRootLogin" /etc/ssh/sshd_config | G5: Не начато
A6: 5 | B6: 1. Безопасность (пароли и ключи) | C6: Включить файервол: открыты только 22, 80, 443 | D6: Я | E6: Высокий | F6: ufw status | G6: Готово
A7: 6 | B7: 1. Безопасность (пароли и ключи) | C7: Включить fail2ban (защита от подбора паролей SSH) | D7: Я | E7: Средний | F7: systemctl status fail2ban | G7: Готово
A8: 7 | B8: 1. Безопасность (пароли и ключи) | C8: Сменить секрет Cloudflare Worker (relay Telegram), если он светился | D8: Вы | E8: Средний | G8: Не начато
A9: 8 | B9: 1. Безопасность (пароли и ключи) | C9: Проверить, что секретов нет в репозитории GitHub (и репозиторий приватный) | D9: Я | E9: Высокий | G9: Не начато
A10: 9 | B10: 1. Безопасность (пароли и ключи) | C10: Накатить обновления Ubuntu (240 пакетов), перезагрузить сервер в удобное время | D10: Вы + я | E10: Средний | F10: apt update && apt upgrade -y (до переезда, не во время) | G10: Не начато
A11: 10 | B11: 2. Оптимизация | C11: ВЕРНУТЬ фоновый приоритет синхронизации (убрать форсированный режим), удалить drop-in boost.conf | D11: Я | E11: Высокий | F11: rm /etc/systemd/system/bs-sync.service.d/boost.conf && systemctl daemon-reload | G11: Не начато
A12: 11 | B12: 2. Оптимизация | C12: Включить почасовую синхронизацию (bs-sync.timer) после окончания первого полного прогона | D12: Вы + я | E12: Высокий | F12: systemctl enable --now bs-sync.timer | G12: Не начато
A13: 12 | B13: 2. Оптимизация | C13: wm-check: сохранять кэш каждые 100 позиций (сейчас пишется только в конце, прерывание = начало с нуля) | D13: Я | E13: Средний | F13: Доработка кода | G13: Готово | H13: Сделано в коде; на сервере появится после update.sh
A14: 13 | B14: 2. Оптимизация | C14: Применить настройку nginx (кэш, защита от перегрузки): deploy/tune-nginx.sh | D14: Вы + я | E14: Высокий | F14: bash /opt/salut38-src/deploy/tune-nginx.sh | G14: Не начато
A15: 14 | B15: 2. Оптимизация | C15: Cloudflare перед сайтом при переезде (кэш статики, защита от DDoS) | D15: Вы + я | E15: Высокий | F15: Делаем вместе при смене DNS | G15: Не начато
A16: 15 | B16: 2. Оптимизация | C16: Ротация логов и очистка: journald, nginx, /tmp (не переполнить диск 40 ГБ) | D16: Я | E16: Средний | G16: Не начато
A17: 16 | B17: 2. Оптимизация | C17: Резервные копии: /var/lib/bs-data (заказы, пользователи, кэши) — ежедневно, хранить 14 дней; проверить восстановление | D17: Я | E17: Высокий | F17: Заказы — самые ценные данные | G17: Не начато
A18: 17 | B18: 2. Оптимизация | C18: Проверить мониторинг: тестовое оповещение о нагрузке >80% и о новом заказе приходит в бота | D18: Вы + я | E18: Средний | G18: Не начато
A19: 18 | B19: 2. Оптимизация | C19: Проверка скорости сайта на телефоне (Lighthouse), размер картинок и видео | D19: Я | E19: Средний | G19: Не начато
A20: 19 | B20: 2. Оптимизация | C20: Старые картинки InSales у существующих товаров: сравнить с картинками поставщика и предложить замену там, где у поставщика заметно лучше | D20: Вы + я | E20: Низкий | F20: Решаем после переезда | G20: Не начато
A21: 20 | B21: 3. Каталог и данные | C21: Дождаться конца полной проверки водяных знаков (wm-check), проверить итог в журнале | D21: Вы | E21: Высокий | F21: journalctl -u bs-sync --no-pager | grep -E "Проверено|Видео|Длина" | G21: Не начато
A22: 21 | B22: 3. Каталог и данные | C22: Просмотреть раздел «Требуют внимания» (≈65 позиций): 🔴 скрыты, 🟡 показаны — решить по каждой | D22: Вы | E22: Высокий | F22: Приложение заказов → Товары → ⚠ | G22: Не начато
A23: 22 | B23: 3. Каталог и данные | C23: Выкатить характеристики от поставщика (время работы, размер, высота) и проверить карточки: MC143, «Не звезди!» (БС754), «Душа нараспашку» | D23: Вы | E23: Высокий | F23: bash /opt/salut38-src/deploy/update.sh (дважды) | G23: Не начато
A24: 23 | B24: 3. Каталог и данные | C24: Отправить письмо программисту поставщика: все характеристики в API + как отправлять заказы | D24: Вы | E24: Высокий | F24: Текст письма у меня готов | G24: Не начато
A25: 24 | B25: 3. Каталог и данные | C25: Решить судьбу категорий «Сигнал охотника» и «Наборы (Россия)» (сейчас не на сайте) | D25: Вы | E25: Средний | G25: Не начато
A26: 25 | B26: 3. Каталог и данные | C26: MC146: проверить переименование «Explosive!» → «Русская душа» (возможное совпадение с PC9230) | D26: Вы | E26: Низкий | G26: Не начато
A27: 26 | B27: 3. Каталог и данные | C27: Просмотреть список скрытых товаров (нет у поставщика) — нет ли ошибок | D27: Вы | E27: Средний | G27: Не начато
A28: 27 | B28: 3. Каталог и данные | C28: Включить низкое-качество-проверку для старых картинок InSales (предложено) | D28: Вы | E28: Низкий | G28: Не начато
A29: 28 | B29: 4. Приложение заказов | C29: Проверить редактирование заказа (✏️) на всех стадиях и историю правок | D29: Вы | E29: Высокий | G29: Не начато
A30: 29 | B30: 4. Приложение заказов | C30: Заново собрать роли сотрудников (сейчас одна роль «Владелец»), затем проверить форму создания сотрудника | D30: Вы + я | E30: Средний | F30: Отдельная задача после переезда | G30: Не начато
A31: 30 | B31: 4. Приложение заказов | C31: Автоотправка заказа поставщику: подключить после получения документации по API заказов | D31: Я | E31: Средний | F31: Ждём ответ поставщика | G31: Не начато
A32: 31 | B32: 4. Приложение заказов | C32: Тестовый заказ целиком: сайт → уведомление в Telegram → приложение → статусы | D32: Вы + я | E32: Высокий | G32: Не начато
A33: 32 | B33: 5. Переезд на salut38.shop | C33: DNS: A-запись домена на 80.78.245.34 (через Cloudflare), срок обновления 5–60 мин | D33: Вы | E33: Высокий | G33: Не начато
A34: 33 | B34: 5. Переезд на salut38.shop | C34: Сертификат Let's Encrypt для salut38.shop и app.salut38.shop (certbot), автопродление | D34: Я | E34: Высокий | G34: Не начато
A35: 34 | B35: 5. Переезд на salut38.shop | C35: Изменить BASE/nginx под новый домен; убрать временный noindex и robots-temp | D35: Я | E35: Высокий | F35: update.sh без режима temp | G35: Не начато
A36: 35 | B36: 5. Переезд на salut38.shop | C36: 301-редиректы со старого сайта (адреса товаров) на новый, sitemap.xml, robots.txt | D36: Я | E36: Высокий | G36: Не начато
A37: 36 | B37: 5. Переезд на salut38.shop | C37: Яндекс.Вебмастер и Метрика: добавить новый домен, подтвердить, отправить sitemap | D37: Вы + я | E37: Средний | G37: Не начато
A38: 37 | B38: 5. Переезд на salut38.shop | C38: Проверить ссылки в Telegram-боте, приложении, QR-коде дисконтной карты и в рекламе на новый домен | D38: Вы | E38: Средний | G38: Не начато
A39: 38 | B39: 5. Переезд на salut38.shop | C39: Окно переезда ночью; план отката (вернуть DNS, оставить старый сайт 2–3 дня) | D39: Вы + я | E39: Высокий | G39: Не начато
A40: 39 | B40: 6. Юридическое | C40: Политика конфиденциальности, согласие на обработку персональных данных, публичная оферта на сайте | D40: Вы | E40: Высокий | F40: Данные клиентов собираем в заказах | G40: Не начато
...

Sheet Итог
A1: Блок | B1: Всего | C1: Готово | D1: Осталось
A2: 1. Безопасность (пароли и ключи) | B2: =COUNTIF(Чек-лист!B:B,A2) | C2: =COUNTIFS(Чек-лист!B:B,A2,Чек-лист!G:G,"Готово") | D2: =B2-C2
A3: 2. Оптимизация | B3: =COUNTIF(Чек-лист!B:B,A3) | C3: =COUNTIFS(Чек-лист!B:B,A3,Чек-лист!G:G,"Готово") | D3: =B3-C3
A4: 3. Каталог и данные | B4: =COUNTIF(Чек-лист!B:B,A4) | C4: =COUNTIFS(Чек-лист!B:B,A4,Чек-лист!G:G,"Готово") | D4: =B4-C4
A5: 4. Приложение заказов | B5: =COUNTIF(Чек-лист!B:B,A5) | C5: =COUNTIFS(Чек-лист!B:B,A5,Чек-лист!G:G,"Готово") | D5: =B5-C5
A6: 5. Переезд на salut38.shop | B6: =COUNTIF(Чек-лист!B:B,A6) | C6: =COUNTIFS(Чек-лист!B:B,A6,Чек-лист!G:G,"Готово") | D6: =B6-C6
A7: 6. Юридическое | B7: =COUNTIF(Чек-лист!B:B,A7) | C7: =COUNTIFS(Чек-лист!B:B,A7,Чек-лист!G:G,"Готово") | D7: =B7-C7
A8: 7. Подписчики и бот | B8: =COUNTIF(Чек-лист!B:B,A8) | C8: =COUNTIFS(Чек-лист!B:B,A8,Чек-лист!G:G,"Готово") | D8: =B8-C8
A9: Всего | B9: =SUM(B2:B8) | C9: =SUM(C2:C8) | D9: =SUM(D2:D8)
